{
   "assignee" : null,
   "body" : "Looks like it fixes #8045.\r\n\r\nI cannot explain the failure (it happens 100% reproducibly for me, with a clean cache and no other bitcoind running, even when running outside of rpc-tests.py):\r\n```\r\n$ ./walletbackup.py \r\nINFO: Initializing test directory /tmp/testnfwna8uq\r\nINFO: Generating initial blockchain\r\nINFO: Creating transactions\r\nINFO: Backing up\r\nINFO: More transactions\r\nINFO: Restoring using wallet.dat\r\nINFO: Re-starting nodes\r\nINFO: Restoring using dumped wallet\r\nUnexpected exception caught during testing: BrokenPipeError(32, 'Broken pipe')\r\n  File \"/home/pw/git/bitcoin/qa/rpc-tests/test_framework/test_framework.py\", line 138, in main\r\n    self.run_test()\r\n  File \"./walletbackup.py\", line 193, in run_test\r\n    sync_blocks(self.nodes)\r\n  File \"/home/pw/git/bitcoin/qa/rpc-tests/test_framework/util.py\", line 127, in sync_blocks\r\n    counts = [ x.getblockcount() for x in rpc_connections ]\r\n  File \"/home/pw/git/bitcoin/qa/rpc-tests/test_framework/util.py\", line 127, in <listcomp>\r\n    counts = [ x.getblockcount() for x in rpc_connections ]\r\n  File \"/home/pw/git/bitcoin/qa/rpc-tests/test_framework/coverage.py\", line 49, in __call__\r\n    return_val = self.auth_service_proxy_instance.__call__(*args, **kwargs)\r\n  File \"/home/pw/git/bitcoin/qa/rpc-tests/test_framework/authproxy.py\", line 137, in __call__\r\n    response = self._request('POST', self.__url.path, postdata)\r\n  File \"/home/pw/git/bitcoin/qa/rpc-tests/test_framework/authproxy.py\", line 118, in _request\r\n    self.__conn.request(method, path, postdata, headers)\r\n  File \"/usr/lib/python3.5/http/client.py\", line 1106, in request\r\n    self._send_request(method, url, body, headers)\r\n  File \"/usr/lib/python3.5/http/client.py\", line 1151, in _send_request\r\n    self.endheaders(body)\r\n  File \"/usr/lib/python3.5/http/client.py\", line 1102, in endheaders\r\n    self._send_output(message_body)\r\n  File \"/usr/lib/python3.5/http/client.py\", line 936, in _send_output\r\n    self.send(message_body)\r\n  File \"/usr/lib/python3.5/http/client.py\", line 908, in send\r\n    self.sock.sendall(data)\r\nStopping nodes\r\nWARN: Unable to stop node: CannotSendRequest('Request-sent',)\r\n```\r\n\r\n I also can't explain why Travis doesn't have this problem. I certainly can't explain why this patch fixes it or even remotely has anything to do with the observed problem, but it fixes it 100% reproducibly.",
   "closed_at" : "2016-06-02T17:14:59Z",
   "closed_by" : {
      "avatar_url" : "https://avatars.githubusercontent.com/u/548488?v=3",
      "events_url" : "https://api.github.com/users/sipa/events{/privacy}",
      "followers_url" : "https://api.github.com/users/sipa/followers",
      "following_url" : "https://api.github.com/users/sipa/following{/other_user}",
      "gists_url" : "https://api.github.com/users/sipa/gists{/gist_id}",
      "gravatar_id" : "",
      "html_url" : "https://github.com/sipa",
      "id" : 548488,
      "login" : "sipa",
      "organizations_url" : "https://api.github.com/users/sipa/orgs",
      "received_events_url" : "https://api.github.com/users/sipa/received_events",
      "repos_url" : "https://api.github.com/users/sipa/repos",
      "site_admin" : false,
      "starred_url" : "https://api.github.com/users/sipa/starred{/owner}{/repo}",
      "subscriptions_url" : "https://api.github.com/users/sipa/subscriptions",
      "type" : "User",
      "url" : "https://api.github.com/users/sipa"
   },
   "comments" : 11,
   "comments_url" : "https://api.github.com/repos/bitcoin/bitcoin/issues/8051/comments",
   "created_at" : "2016-05-13T02:52:48Z",
   "events_url" : "https://api.github.com/repos/bitcoin/bitcoin/issues/8051/events",
   "html_url" : "https://github.com/bitcoin/bitcoin/pull/8051",
   "id" : 154623307,
   "labels" : [
      {
         "color" : "d4c5f9",
         "name" : "Tests",
         "url" : "https://api.github.com/repos/bitcoin/bitcoin/labels/Tests"
      }
   ],
   "labels_url" : "https://api.github.com/repos/bitcoin/bitcoin/issues/8051/labels{/name}",
   "locked" : false,
   "milestone" : null,
   "number" : 8051,
   "pull_request" : {
      "diff_url" : "https://github.com/bitcoin/bitcoin/pull/8051.diff",
      "html_url" : "https://github.com/bitcoin/bitcoin/pull/8051",
      "patch_url" : "https://github.com/bitcoin/bitcoin/pull/8051.patch",
      "url" : "https://api.github.com/repos/bitcoin/bitcoin/pulls/8051"
   },
   "repository_url" : "https://api.github.com/repos/bitcoin/bitcoin",
   "state" : "closed",
   "title" : "Seemingly fix walletbackup.py failure",
   "updated_at" : "2016-06-02T17:14:59Z",
   "url" : "https://api.github.com/repos/bitcoin/bitcoin/issues/8051",
   "user" : {
      "avatar_url" : "https://avatars.githubusercontent.com/u/548488?v=3",
      "events_url" : "https://api.github.com/users/sipa/events{/privacy}",
      "followers_url" : "https://api.github.com/users/sipa/followers",
      "following_url" : "https://api.github.com/users/sipa/following{/other_user}",
      "gists_url" : "https://api.github.com/users/sipa/gists{/gist_id}",
      "gravatar_id" : "",
      "html_url" : "https://github.com/sipa",
      "id" : 548488,
      "login" : "sipa",
      "organizations_url" : "https://api.github.com/users/sipa/orgs",
      "received_events_url" : "https://api.github.com/users/sipa/received_events",
      "repos_url" : "https://api.github.com/users/sipa/repos",
      "site_admin" : false,
      "starred_url" : "https://api.github.com/users/sipa/starred{/owner}{/repo}",
      "subscriptions_url" : "https://api.github.com/users/sipa/subscriptions",
      "type" : "User",
      "url" : "https://api.github.com/users/sipa"
   }
}
